<?xml version='1.0' encoding='utf-8'?>
<robot name="double_piper"><link name="base"><inertial /><inertial><origin xyz="0 0 0" rpy="0 0 0" /><mass value="1.0" /><inertia ixx="0.001" ixy="0" ixz="0" iyy="0.001" iyz="0" izz="0.001" /></inertial></link><link name="dummy_link_l" /><link name="base_link_l"><inertial>
      <origin xyz="-0.00473641164191482 2.56829134630247E-05 0.041451518036016" rpy="0 0 0" />
      <mass value="1.02" />
      <inertia ixx="0.00267433" ixy="-0.00000073" ixz="-0.00017389" iyy="0.00282612" iyz="0.0000004" izz="0.00089624" />
    </inertial><visual>
      <origin xyz="0 0 0" rpy="0 0 0" />
      <geometry>
        <mesh filename="package://piper_description/meshes/base_link.STL" />
      </geometry>
      <material name="">
        <color rgba="0.792156862745098 0.819607843137255 0.933333333333333 1" />
      </material>
    </visual><collision>
      <origin xyz="0 0 0" rpy="0 0 0" />
      <geometry>
        <mesh filename="package://piper_description/meshes/base_link.STL" />
      </geometry>
    </collision></link><link name="link1_l"><inertial>
      <origin xyz="0.000121504734057468 0.000104632162460536 -0.00438597309559853" rpy="0 0 0" />
      <mass value="0.71" />
      <inertia ixx="0.00048916" ixy="-0.00000036" ixz="-0.00000224" iyy="0.00040472" iyz="-0.00000242" izz="0.00043982" />
    </inertial><visual>
      <origin xyz="0 0 0" rpy="0 0 0" />
      <geometry>
        <mesh filename="package://piper_description/meshes/link1.STL" />
      </geometry>
      <material name="">
        <color rgba="0.792156862745098 0.819607843137255 0.933333333333333 1" />
      </material>
    </visual><collision>
      <origin xyz="0 0 0" rpy="0 0 0" />
      <geometry>
        <mesh filename="package://piper_description/meshes/link1.STL" />
      </geometry>
    </collision></link><link name="link2_l"><inertial>
      <origin xyz="0.198666145229743 -0.010926924140076 0.00142121714502687" rpy="0 0 0" />
      <mass value="1.17" />
      <inertia ixx="0.00116918" ixy="-0.00180037" ixz="0.00025146" iyy="0.06785384" iyz="-0.00000455" izz="0.06774489" />
    </inertial><visual>
      <origin xyz="0 0 0" rpy="0 0 0" />
      <geometry>
        <mesh filename="package://piper_description/meshes/link2.STL" />
      </geometry>
      <material name="">
        <color rgba="0.792156862745098 0.819607843137255 0.933333333333333 1" />
      </material>
    </visual><collision>
      <origin xyz="0 0 0" rpy="0 0 0" />
      <geometry>
        <mesh filename="package://piper_description/meshes/link2.STL" />
      </geometry>
    </collision></link><link name="link3_l"><inertial>
      <origin xyz="-0.0202737662122021 -0.133914995944595 -0.000458682652737356" rpy="0 0 0" />
      <mass value="0.5" />
      <inertia ixx="0.01361711" ixy="0.00165794" ixz="-0.00000048" iyy="0.00045024" iyz="-0.00000045" izz="0.01380322" />
    </inertial><visual>
      <origin xyz="0 0 0" rpy="0 0 0" />
      <geometry>
        <mesh filename="package://piper_description/meshes/link3.STL" />
      </geometry>
      <material name="">
        <color rgba="0.792156862745098 0.819607843137255 0.933333333333333 1" />
      </material>
    </visual><collision>
      <origin xyz="0 0 0" rpy="0 0 0" />
      <geometry>
        <mesh filename="package://piper_description/meshes/link3.STL" />
      </geometry>
    </collision></link><link name="link4_l"><inertial>
      <origin xyz="-9.66635791618542E-05 0.000876064475651083 -0.00496880904640868" rpy="0 0 0" />
      <mass value="0.38" />
      <inertia ixx="0.00018501" ixy="0.00000054" ixz="0.00000120" iyy="0.00018965" iyz="-0.00000841" izz="0.00015484" />
    </inertial><visual>
      <origin xyz="0 0 0" rpy="0 0 0" />
      <geometry>
        <mesh filename="package://piper_description/meshes/link4.STL" />
      </geometry>
      <material name="">
        <color rgba="0.792156862745098 0.819607843137255 0.933333333333333 1" />
      </material>
    </visual><collision>
      <origin xyz="0 0 0" rpy="0 0 0" />
      <geometry>
        <mesh filename="package://piper_description/meshes/link4.STL" />
      </geometry>
    </collision></link><link name="link5_l"><inertial>
      <origin xyz="-4.10554118924211E-05 -0.0566486692356075 -0.0037205791677906" rpy="0 0 0" />
      <mass value="0.383" />
      <inertia ixx="0.00166169" ixy="0.00000006" ixz="-0.00000007" iyy="0.00018510" iyz="0.00001026" izz="0.00164321" />
    </inertial><visual>
      <origin xyz="0 0 0" rpy="0 0 0" />
      <geometry>
        <mesh filename="package://piper_description/meshes/link5.STL" />
      </geometry>
      <material name="">
        <color rgba="0.792156862745098 0.819607843137255 0.933333333333333 1" />
      </material>
    </visual><collision>
      <origin xyz="0 0 0" rpy="0 0 0" />
      <geometry>
        <mesh filename="package://piper_description/meshes/link5.STL" />
      </geometry>
    </collision></link><link name="link6_l"><inertial>
      <origin xyz="-8.82590762930069E-05 9.0598378529832E-06 -0.002" rpy="0 0 0" />
      <mass value="0.007" />
      <inertia ixx="5.73015540542155E-07" ixy="-1.98305403089247E-22" ixz="-7.2791893904596E-23" iyy="5.73015540542155E-07" iyz="-3.4146026640245E-24" izz="1.06738869138926E-06" />
    </inertial><visual>
      <origin xyz="0 0 0" rpy="0 0 0" />
      <geometry>
        <mesh filename="package://piper_description/meshes/link6.STL" />
      </geometry>
      <material name="">
        <color rgba="0.898039215686275 0.917647058823529 0.929411764705882 1" />
      </material>
    </visual><collision>
      <origin xyz="0 0 0" rpy="0 0 0" />
      <geometry>
        <mesh filename="package://piper_description/meshes/link6.STL" />
      </geometry>
    </collision></link><link name="gripper_base_l"><inertial>
      <origin xyz="-0.000183807162235591 8.05033155577911E-05 0.0321436689908876" rpy="0 0 0" />
      <mass value="0.45" />
      <inertia ixx="0.00092934" ixy="0.00000034" ixz="-0.00000738" iyy="0.00071447" iyz="0.00000005" izz="0.00039442" />
    </inertial><visual>
      <origin xyz="0 0 0" rpy="0 0 0" />
      <geometry>
        <mesh filename="package://piper_description/meshes/gripper_base.STL" />
      </geometry>
      <material name="">
        <color rgba="0.792156862745098 0.819607843137255 0.933333333333333 1" />
      </material>
    </visual><collision>
      <origin xyz="0 0 0" rpy="0 0 0" />
      <geometry>
        <mesh filename="package://piper_description/meshes/gripper_base.STL" />
      </geometry>
    </collision></link><link name="link7_l"><inertial>
      <origin xyz="0.00065123185041968 -0.0491929869131989 0.00972258769184025" rpy="0 0 0" />
      <mass value="0.025" />
      <inertia ixx="0.00007371" ixy="-0.00000113" ixz="0.00000021" iyy="0.00000781" iyz="-0.00001372" izz="0.0000747" />
    </inertial><visual>
      <origin xyz="0 0 0" rpy="0 0 0" />
      <geometry>
        <mesh filename="package://piper_description/meshes/link7.STL" />
      </geometry>
      <material name="">
        <color rgba="0.792156862745098 0.819607843137255 0.933333333333333 1" />
      </material>
    </visual><collision>
      <origin xyz="0 0 0" rpy="0 0 0" />
      <geometry>
        <mesh filename="package://piper_description/meshes/link7.STL" />
      </geometry>
    </collision></link><link name="link8_l"><inertial>
      <origin xyz="0.000651231850419722 -0.0491929869131991 0.00972258769184024" rpy="0 0 0" />
      <mass value="0.025" />
      <inertia ixx="0.00007371" ixy="-0.00000113" ixz="0.00000021" iyy="0.00000781" iyz="-0.00001372" izz="0.0000747" />
    </inertial><visual>
      <origin xyz="0 0 0" rpy="0 0 0" />
      <geometry>
        <mesh filename="package://piper_description/meshes/link8.STL" />
      </geometry>
      <material name="">
        <color rgba="0.792156862745098 0.819607843137255 0.933333333333333 1" />
      </material>
    </visual><collision>
      <origin xyz="0 0 0" rpy="0 0 0" />
      <geometry>
        <mesh filename="package://piper_description/meshes/link8.STL" />
      </geometry>
    </collision></link><joint name="base_to_dummy_l" type="fixed"><parent link="dummy_link_l" /><child link="base_link_l" /><origin xyz="0 0 0" rpy="0 0 0" /></joint><joint name="joint1_l" type="revolute"><origin xyz="0 0 0.123" rpy="0 0 0" /><parent link="base_link_l" /><child link="link1_l" /><axis xyz="0 0 1" /><limit lower="-2.618" upper="2.618" effort="100" velocity="5" /></joint><joint name="joint2_l" type="revolute"><origin xyz="0 0 0" rpy="1.5708 -0.1359 -3.1416" /><parent link="link1_l" /><child link="link2_l" /><axis xyz="0 0 1" /><limit lower="0" upper="3.14" effort="100" velocity="5" /></joint><joint name="joint3_l" type="revolute"><origin xyz="0.28503 0 0" rpy="0 0 -1.7939" /><parent link="link2_l" /><child link="link3_l" /><axis xyz="0 0 1" /><limit lower="-2.967" upper="0" effort="100" velocity="5" /></joint><joint name="joint4_l" type="revolute"><origin xyz="-0.021984 -0.25075 0" rpy="1.5708 0 0" /><parent link="link3_l" /><child link="link4_l" /><axis xyz="0 0 1" /><limit lower="-1.745" upper="1.745" effort="100" velocity="5" /></joint><joint name="joint5_l" type="revolute"><origin xyz="0 0 0" rpy="-1.5708 0 0" /><parent link="link4_l" /><child link="link5_l" /><axis xyz="0 0 1" /><limit lower="-1.22" upper="1.22" effort="100" velocity="5" /></joint><joint name="joint6_l" type="revolute"><origin xyz="8.8259E-05 -0.091 0" rpy="1.5708 0 0" /><parent link="link5_l" /><child link="link6_l" /><axis xyz="0 0 1" /><limit lower="-2.0944" upper="2.0944" effort="100" velocity="3" /></joint><joint name="joint6_to_gripper_base_l" type="fixed"><origin xyz="0 0 0" rpy="0 0 0" /><parent link="link6_l" /><child link="gripper_base_l" /></joint><joint name="joint7_l" type="prismatic"><origin xyz="0 0 0.1358" rpy="1.5708 0 0" /><parent link="gripper_base_l" /><child link="link7_l" /><axis xyz="0 0 1" /><limit lower="0" upper="0.035" effort="100" velocity="1" /></joint><joint name="joint8_l" type="prismatic"><origin xyz="0 0 0.1358" rpy="1.5708 0 -3.1416" /><parent link="gripper_base_l" /><child link="link8_l" /><axis xyz="0 0 -1" /><limit lower="-0.035" upper="0" effort="100" velocity="1" /></joint><joint name="base_to_l_arm" type="fixed"><parent link="base" /><child link="dummy_link_l" /><origin xyz="0 0.15 0" rpy="0 0 0" /></joint><link name="dummy_link_r" /><link name="base_link_r"><inertial>
      <origin xyz="-0.00473641164191482 2.56829134630247E-05 0.041451518036016" rpy="0 0 0" />
      <mass value="1.02" />
      <inertia ixx="0.00267433" ixy="-0.00000073" ixz="-0.00017389" iyy="0.00282612" iyz="0.0000004" izz="0.00089624" />
    </inertial><visual>
      <origin xyz="0 0 0" rpy="0 0 0" />
      <geometry>
        <mesh filename="package://piper_description/meshes/base_link.STL" />
      </geometry>
      <material name="">
        <color rgba="0.792156862745098 0.819607843137255 0.933333333333333 1" />
      </material>
    </visual><collision>
      <origin xyz="0 0 0" rpy="0 0 0" />
      <geometry>
        <mesh filename="package://piper_description/meshes/base_link.STL" />
      </geometry>
    </collision></link><link name="link1_r"><inertial>
      <origin xyz="0.000121504734057468 0.000104632162460536 -0.00438597309559853" rpy="0 0 0" />
      <mass value="0.71" />
      <inertia ixx="0.00048916" ixy="-0.00000036" ixz="-0.00000224" iyy="0.00040472" iyz="-0.00000242" izz="0.00043982" />
    </inertial><visual>
      <origin xyz="0 0 0" rpy="0 0 0" />
      <geometry>
        <mesh filename="package://piper_description/meshes/link1.STL" />
      </geometry>
      <material name="">
        <color rgba="0.792156862745098 0.819607843137255 0.933333333333333 1" />
      </material>
    </visual><collision>
      <origin xyz="0 0 0" rpy="0 0 0" />
      <geometry>
        <mesh filename="package://piper_description/meshes/link1.STL" />
      </geometry>
    </collision></link><link name="link2_r"><inertial>
      <origin xyz="0.198666145229743 -0.010926924140076 0.00142121714502687" rpy="0 0 0" />
      <mass value="1.17" />
      <inertia ixx="0.00116918" ixy="-0.00180037" ixz="0.00025146" iyy="0.06785384" iyz="-0.00000455" izz="0.06774489" />
    </inertial><visual>
      <origin xyz="0 0 0" rpy="0 0 0" />
      <geometry>
        <mesh filename="package://piper_description/meshes/link2.STL" />
      </geometry>
      <material name="">
        <color rgba="0.792156862745098 0.819607843137255 0.933333333333333 1" />
      </material>
    </visual><collision>
      <origin xyz="0 0 0" rpy="0 0 0" />
      <geometry>
        <mesh filename="package://piper_description/meshes/link2.STL" />
      </geometry>
    </collision></link><link name="link3_r"><inertial>
      <origin xyz="-0.0202737662122021 -0.133914995944595 -0.000458682652737356" rpy="0 0 0" />
      <mass value="0.5" />
      <inertia ixx="0.01361711" ixy="0.00165794" ixz="-0.00000048" iyy="0.00045024" iyz="-0.00000045" izz="0.01380322" />
    </inertial><visual>
      <origin xyz="0 0 0" rpy="0 0 0" />
      <geometry>
        <mesh filename="package://piper_description/meshes/link3.STL" />
      </geometry>
      <material name="">
        <color rgba="0.792156862745098 0.819607843137255 0.933333333333333 1" />
      </material>
    </visual><collision>
      <origin xyz="0 0 0" rpy="0 0 0" />
      <geometry>
        <mesh filename="package://piper_description/meshes/link3.STL" />
      </geometry>
    </collision></link><link name="link4_r"><inertial>
      <origin xyz="-9.66635791618542E-05 0.000876064475651083 -0.00496880904640868" rpy="0 0 0" />
      <mass value="0.38" />
      <inertia ixx="0.00018501" ixy="0.00000054" ixz="0.00000120" iyy="0.00018965" iyz="-0.00000841" izz="0.00015484" />
    </inertial><visual>
      <origin xyz="0 0 0" rpy="0 0 0" />
      <geometry>
        <mesh filename="package://piper_description/meshes/link4.STL" />
      </geometry>
      <material name="">
        <color rgba="0.792156862745098 0.819607843137255 0.933333333333333 1" />
      </material>
    </visual><collision>
      <origin xyz="0 0 0" rpy="0 0 0" />
      <geometry>
        <mesh filename="package://piper_description/meshes/link4.STL" />
      </geometry>
    </collision></link><link name="link5_r"><inertial>
      <origin xyz="-4.10554118924211E-05 -0.0566486692356075 -0.0037205791677906" rpy="0 0 0" />
      <mass value="0.383" />
      <inertia ixx="0.00166169" ixy="0.00000006" ixz="-0.00000007" iyy="0.00018510" iyz="0.00001026" izz="0.00164321" />
    </inertial><visual>
      <origin xyz="0 0 0" rpy="0 0 0" />
      <geometry>
        <mesh filename="package://piper_description/meshes/link5.STL" />
      </geometry>
      <material name="">
        <color rgba="0.792156862745098 0.819607843137255 0.933333333333333 1" />
      </material>
    </visual><collision>
      <origin xyz="0 0 0" rpy="0 0 0" />
      <geometry>
        <mesh filename="package://piper_description/meshes/link5.STL" />
      </geometry>
    </collision></link><link name="link6_r"><inertial>
      <origin xyz="-8.82590762930069E-05 9.0598378529832E-06 -0.002" rpy="0 0 0" />
      <mass value="0.007" />
      <inertia ixx="5.73015540542155E-07" ixy="-1.98305403089247E-22" ixz="-7.2791893904596E-23" iyy="5.73015540542155E-07" iyz="-3.4146026640245E-24" izz="1.06738869138926E-06" />
    </inertial><visual>
      <origin xyz="0 0 0" rpy="0 0 0" />
      <geometry>
        <mesh filename="package://piper_description/meshes/link6.STL" />
      </geometry>
      <material name="">
        <color rgba="0.898039215686275 0.917647058823529 0.929411764705882 1" />
      </material>
    </visual><collision>
      <origin xyz="0 0 0" rpy="0 0 0" />
      <geometry>
        <mesh filename="package://piper_description/meshes/link6.STL" />
      </geometry>
    </collision></link><link name="gripper_base_r"><inertial>
      <origin xyz="-0.000183807162235591 8.05033155577911E-05 0.0321436689908876" rpy="0 0 0" />
      <mass value="0.45" />
      <inertia ixx="0.00092934" ixy="0.00000034" ixz="-0.00000738" iyy="0.00071447" iyz="0.00000005" izz="0.00039442" />
    </inertial><visual>
      <origin xyz="0 0 0" rpy="0 0 0" />
      <geometry>
        <mesh filename="package://piper_description/meshes/gripper_base.STL" />
      </geometry>
      <material name="">
        <color rgba="0.792156862745098 0.819607843137255 0.933333333333333 1" />
      </material>
    </visual><collision>
      <origin xyz="0 0 0" rpy="0 0 0" />
      <geometry>
        <mesh filename="package://piper_description/meshes/gripper_base.STL" />
      </geometry>
    </collision></link><link name="link7_r"><inertial>
      <origin xyz="0.00065123185041968 -0.0491929869131989 0.00972258769184025" rpy="0 0 0" />
      <mass value="0.025" />
      <inertia ixx="0.00007371" ixy="-0.00000113" ixz="0.00000021" iyy="0.00000781" iyz="-0.00001372" izz="0.0000747" />
    </inertial><visual>
      <origin xyz="0 0 0" rpy="0 0 0" />
      <geometry>
        <mesh filename="package://piper_description/meshes/link7.STL" />
      </geometry>
      <material name="">
        <color rgba="0.792156862745098 0.819607843137255 0.933333333333333 1" />
      </material>
    </visual><collision>
      <origin xyz="0 0 0" rpy="0 0 0" />
      <geometry>
        <mesh filename="package://piper_description/meshes/link7.STL" />
      </geometry>
    </collision></link><link name="link8_r"><inertial>
      <origin xyz="0.000651231850419722 -0.0491929869131991 0.00972258769184024" rpy="0 0 0" />
      <mass value="0.025" />
      <inertia ixx="0.00007371" ixy="-0.00000113" ixz="0.00000021" iyy="0.00000781" iyz="-0.00001372" izz="0.0000747" />
    </inertial><visual>
      <origin xyz="0 0 0" rpy="0 0 0" />
      <geometry>
        <mesh filename="package://piper_description/meshes/link8.STL" />
      </geometry>
      <material name="">
        <color rgba="0.792156862745098 0.819607843137255 0.933333333333333 1" />
      </material>
    </visual><collision>
      <origin xyz="0 0 0" rpy="0 0 0" />
      <geometry>
        <mesh filename="package://piper_description/meshes/link8.STL" />
      </geometry>
    </collision></link><joint name="base_to_dummy_r" type="fixed"><parent link="dummy_link_r" /><child link="base_link_r" /><origin xyz="0 0 0" rpy="0 0 0" /></joint><joint name="joint1_r" type="revolute"><origin xyz="0 0 0.123" rpy="0 0 0" /><parent link="base_link_r" /><child link="link1_r" /><axis xyz="0 0 1" /><limit lower="-2.618" upper="2.618" effort="100" velocity="5" /></joint><joint name="joint2_r" type="revolute"><origin xyz="0 0 0" rpy="1.5708 -0.1359 -3.1416" /><parent link="link1_r" /><child link="link2_r" /><axis xyz="0 0 1" /><limit lower="0" upper="3.14" effort="100" velocity="5" /></joint><joint name="joint3_r" type="revolute"><origin xyz="0.28503 0 0" rpy="0 0 -1.7939" /><parent link="link2_r" /><child link="link3_r" /><axis xyz="0 0 1" /><limit lower="-2.967" upper="0" effort="100" velocity="5" /></joint><joint name="joint4_r" type="revolute"><origin xyz="-0.021984 -0.25075 0" rpy="1.5708 0 0" /><parent link="link3_r" /><child link="link4_r" /><axis xyz="0 0 1" /><limit lower="-1.745" upper="1.745" effort="100" velocity="5" /></joint><joint name="joint5_r" type="revolute"><origin xyz="0 0 0" rpy="-1.5708 0 0" /><parent link="link4_r" /><child link="link5_r" /><axis xyz="0 0 1" /><limit lower="-1.22" upper="1.22" effort="100" velocity="5" /></joint><joint name="joint6_r" type="revolute"><origin xyz="8.8259E-05 -0.091 0" rpy="1.5708 0 0" /><parent link="link5_r" /><child link="link6_r" /><axis xyz="0 0 1" /><limit lower="-2.0944" upper="2.0944" effort="100" velocity="3" /></joint><joint name="joint6_to_gripper_base_r" type="fixed"><origin xyz="0 0 0" rpy="0 0 0" /><parent link="link6_r" /><child link="gripper_base_r" /></joint><joint name="joint7_r" type="prismatic"><origin xyz="0 0 0.1358" rpy="1.5708 0 0" /><parent link="gripper_base_r" /><child link="link7_r" /><axis xyz="0 0 1" /><limit lower="0" upper="0.035" effort="100" velocity="1" /></joint><joint name="joint8_r" type="prismatic"><origin xyz="0 0 0.1358" rpy="1.5708 0 -3.1416" /><parent link="gripper_base_r" /><child link="link8_r" /><axis xyz="0 0 -1" /><limit lower="-0.035" upper="0" effort="100" velocity="1" /></joint><joint name="base_to_r_arm" type="fixed"><parent link="base" /><child link="dummy_link_r" /><origin xyz="0 -0.15 0" rpy="0 0 0" /></joint></robot>